[2025-04-30T23:42:54.268+0000] {local_task_job_runner.py:123} INFO - ::group::Pre task execution logs
[2025-04-30T23:42:54.292+0000] {taskinstance.py:2614} INFO - Dependencies all met for dep_context=non-requeueable deps ti=<TaskInstance: test_snowflake_connection.test_snowflake_connection manual__2025-04-30T23:42:40.191819+00:00 [queued]>
[2025-04-30T23:42:54.308+0000] {taskinstance.py:2614} INFO - Dependencies all met for dep_context=requeueable deps ti=<TaskInstance: test_snowflake_connection.test_snowflake_connection manual__2025-04-30T23:42:40.191819+00:00 [queued]>
[2025-04-30T23:42:54.309+0000] {taskinstance.py:2867} INFO - Starting attempt 1 of 2
[2025-04-30T23:42:54.328+0000] {taskinstance.py:2890} INFO - Executing <Task(SnowflakeCheckOperator): test_snowflake_connection> on 2025-04-30 23:42:40.191819+00:00
[2025-04-30T23:42:54.357+0000] {standard_task_runner.py:104} INFO - Running: ['***', 'tasks', 'run', 'test_snowflake_connection', 'test_snowflake_connection', 'manual__2025-04-30T23:42:40.191819+00:00', '--job-id', '10', '--raw', '--subdir', 'DAGS_FOLDER/test.py', '--cfg-path', '/tmp/tmpptro7snk']
[2025-04-30T23:42:54.360+0000] {standard_task_runner.py:105} INFO - Job 10: Subtask test_snowflake_connection
[2025-04-30T23:42:54.363+0000] {logging_mixin.py:190} WARNING - /home/***/.local/lib/python3.12/site-packages/***/task/task_runner/standard_task_runner.py:70 DeprecationWarning: This process (pid=31) is multi-threaded, use of fork() may lead to deadlocks in the child.
[2025-04-30T23:42:54.365+0000] {standard_task_runner.py:72} INFO - Started process 38 to run task
[2025-04-30T23:42:54.448+0000] {task_command.py:467} INFO - Running <TaskInstance: test_snowflake_connection.test_snowflake_connection manual__2025-04-30T23:42:40.191819+00:00 [running]> on host a4d07d983aa5
[2025-04-30T23:42:54.889+0000] {taskinstance.py:3134} INFO - Exporting env vars: AIRFLOW_CTX_DAG_OWNER='***' AIRFLOW_CTX_DAG_ID='test_snowflake_connection' AIRFLOW_CTX_TASK_ID='test_snowflake_connection' AIRFLOW_CTX_EXECUTION_DATE='2025-04-30T23:42:40.191819+00:00' AIRFLOW_CTX_TRY_NUMBER='1' AIRFLOW_CTX_DAG_RUN_ID='manual__2025-04-30T23:42:40.191819+00:00'
[2025-04-30T23:42:54.891+0000] {taskinstance.py:732} INFO - ::endgroup::
[2025-04-30T23:42:54.995+0000] {sql.py:815} INFO - Executing SQL check: SELECT 1;
[2025-04-30T23:42:55.013+0000] {base.py:84} INFO - Retrieving connection 'snowflake_default'
[2025-04-30T23:42:55.352+0000] {base.py:84} INFO - Retrieving connection 'snowflake_default'
[2025-04-30T23:42:55.356+0000] {connection.py:424} INFO - Snowflake Connector for Python Version: 3.13.2, Python Version: 3.12.9, Platform: Linux-5.15.167.4-microsoft-standard-WSL2-x86_64-with-glibc2.36
[2025-04-30T23:42:55.358+0000] {connection.py:1213} INFO - Connecting to GLOBAL Snowflake domain
[2025-04-30T23:42:55.359+0000] {connection.py:1295} INFO - This connection is in OCSP Fail Open Mode. TLS Certificates would be checked for validity and revocation status. Any other Certificate Revocation related exceptions or OCSP Responder failures would be disregarded in favor of connectivity.
[2025-04-30T23:42:57.697+0000] {connection.py:547} WARNING - Certificate did not match expected hostname: gkexgfn-mc38946.aws_eu_west_3.snowflakecomputing.com. Certificate: {'subject': ((('commonName', '*.prod3.us-west-2.snowflakecomputing.com'),),), 'subjectAltName': [('DNS', '*.prod3.us-west-2.snowflakecomputing.com'), ('DNS', '*.us-west-2.snowflakecomputing.com'), ('DNS', '*.global.snowflakecomputing.com'), ('DNS', '*.snowflakecomputing.com'), ('DNS', '*.prod3.us-west-2.aws.snowflakecomputing.com')]}
[2025-04-30T23:42:57.699+0000] {connectionpool.py:824} WARNING - Retrying (Retry(total=0, connect=None, read=None, redirect=None, status=None)) after connection broken by 'SSLError(CertificateError("hostname 'gkexgfn-mc38946.aws_eu_west_3.snowflakecomputing.com' doesn't match either of '*.prod3.us-west-2.snowflakecomputing.com', '*.us-west-2.snowflakecomputing.com', '*.global.snowflakecomputing.com', '*.snowflakecomputing.com', '*.prod3.us-west-2.aws.snowflakecomputing.com'"))': /session/v1/login-request?request_id=7d7a2e95-fb3a-4652-9181-7d48da37d5a3&databaseName=VOITURE_DATA&schemaName=PUBLIC&warehouse=COMPUTE_WH&roleName=ACCOUNTADMIN&request_guid=fa2cb6c4-0ab7-430b-b042-e9600eca789f
[2025-04-30T23:42:58.356+0000] {connection.py:547} WARNING - Certificate did not match expected hostname: gkexgfn-mc38946.aws_eu_west_3.snowflakecomputing.com. Certificate: {'subject': ((('commonName', '*.prod3.us-west-2.snowflakecomputing.com'),),), 'subjectAltName': [('DNS', '*.prod3.us-west-2.snowflakecomputing.com'), ('DNS', '*.us-west-2.snowflakecomputing.com'), ('DNS', '*.global.snowflakecomputing.com'), ('DNS', '*.snowflakecomputing.com'), ('DNS', '*.prod3.us-west-2.aws.snowflakecomputing.com')]}
[2025-04-30T23:43:00.098+0000] {connection.py:547} WARNING - Certificate did not match expected hostname: gkexgfn-mc38946.aws_eu_west_3.snowflakecomputing.com. Certificate: {'subject': ((('commonName', '*.prod3.us-west-2.snowflakecomputing.com'),),), 'subjectAltName': [('DNS', '*.prod3.us-west-2.snowflakecomputing.com'), ('DNS', '*.us-west-2.snowflakecomputing.com'), ('DNS', '*.global.snowflakecomputing.com'), ('DNS', '*.snowflakecomputing.com'), ('DNS', '*.prod3.us-west-2.aws.snowflakecomputing.com')]}
[2025-04-30T23:43:00.100+0000] {connectionpool.py:824} WARNING - Retrying (Retry(total=0, connect=None, read=None, redirect=None, status=None)) after connection broken by 'SSLError(CertificateError("hostname 'gkexgfn-mc38946.aws_eu_west_3.snowflakecomputing.com' doesn't match either of '*.prod3.us-west-2.snowflakecomputing.com', '*.us-west-2.snowflakecomputing.com', '*.global.snowflakecomputing.com', '*.snowflakecomputing.com', '*.prod3.us-west-2.aws.snowflakecomputing.com'"))': /session/v1/login-request?request_id=90cda0f1-25c3-4c9e-a8c2-e3c6f33c1db6&databaseName=VOITURE_DATA&schemaName=PUBLIC&warehouse=COMPUTE_WH&roleName=ACCOUNTADMIN&request_guid=c639cf89-c209-4763-8aa3-c8c4642fa86a
[2025-04-30T23:43:00.938+0000] {connection.py:547} WARNING - Certificate did not match expected hostname: gkexgfn-mc38946.aws_eu_west_3.snowflakecomputing.com. Certificate: {'subject': ((('commonName', '*.prod3.us-west-2.snowflakecomputing.com'),),), 'subjectAltName': [('DNS', '*.prod3.us-west-2.snowflakecomputing.com'), ('DNS', '*.us-west-2.snowflakecomputing.com'), ('DNS', '*.global.snowflakecomputing.com'), ('DNS', '*.snowflakecomputing.com'), ('DNS', '*.prod3.us-west-2.aws.snowflakecomputing.com')]}
[2025-04-30T23:43:00.950+0000] {taskinstance.py:3313} ERROR - Task failed with exception
Traceback (most recent call last):
  File "/home/airflow/.local/lib/python3.12/site-packages/snowflake/connector/vendored/urllib3/connectionpool.py", line 715, in urlopen
    httplib_response = self._make_request(
                       ^^^^^^^^^^^^^^^^^^^
  File "/home/airflow/.local/lib/python3.12/site-packages/snowflake/connector/vendored/urllib3/connectionpool.py", line 404, in _make_request
    self._validate_conn(conn)
  File "/home/airflow/.local/lib/python3.12/site-packages/snowflake/connector/vendored/urllib3/connectionpool.py", line 1058, in _validate_conn
    conn.connect()
  File "/home/airflow/.local/lib/python3.12/site-packages/snowflake/connector/vendored/urllib3/connection.py", line 472, in connect
    _match_hostname(cert, self.assert_hostname or server_hostname)
  File "/home/airflow/.local/lib/python3.12/site-packages/snowflake/connector/vendored/urllib3/connection.py", line 545, in _match_hostname
    match_hostname(cert, asserted_hostname)
  File "/home/airflow/.local/lib/python3.12/site-packages/snowflake/connector/vendored/urllib3/util/ssl_match_hostname.py", line 150, in match_hostname
    raise CertificateError(
snowflake.connector.vendored.urllib3.util.ssl_match_hostname.CertificateError: hostname 'gkexgfn-mc38946.aws_eu_west_3.snowflakecomputing.com' doesn't match either of '*.prod3.us-west-2.snowflakecomputing.com', '*.us-west-2.snowflakecomputing.com', '*.global.snowflakecomputing.com', '*.snowflakecomputing.com', '*.prod3.us-west-2.aws.snowflakecomputing.com'

During handling of the above exception, another exception occurred:

Traceback (most recent call last):
  File "/home/airflow/.local/lib/python3.12/site-packages/snowflake/connector/vendored/requests/adapters.py", line 486, in send
    resp = conn.urlopen(
           ^^^^^^^^^^^^^
  File "/home/airflow/.local/lib/python3.12/site-packages/snowflake/connector/vendored/urllib3/connectionpool.py", line 827, in urlopen
    return self.urlopen(
           ^^^^^^^^^^^^^
  File "/home/airflow/.local/lib/python3.12/site-packages/snowflake/connector/vendored/urllib3/connectionpool.py", line 799, in urlopen
    retries = retries.increment(
              ^^^^^^^^^^^^^^^^^^
  File "/home/airflow/.local/lib/python3.12/site-packages/snowflake/connector/vendored/urllib3/util/retry.py", line 592, in increment
    raise MaxRetryError(_pool, url, error or ResponseError(cause))
snowflake.connector.vendored.urllib3.exceptions.MaxRetryError: HTTPSConnectionPool(host='gkexgfn-mc38946.aws_eu_west_3.snowflakecomputing.com', port=443): Max retries exceeded with url: /session/v1/login-request?request_id=7d7a2e95-fb3a-4652-9181-7d48da37d5a3&databaseName=VOITURE_DATA&schemaName=PUBLIC&warehouse=COMPUTE_WH&roleName=ACCOUNTADMIN&request_guid=fa2cb6c4-0ab7-430b-b042-e9600eca789f (Caused by SSLError(CertificateError("hostname 'gkexgfn-mc38946.aws_eu_west_3.snowflakecomputing.com' doesn't match either of '*.prod3.us-west-2.snowflakecomputing.com', '*.us-west-2.snowflakecomputing.com', '*.global.snowflakecomputing.com', '*.snowflakecomputing.com', '*.prod3.us-west-2.aws.snowflakecomputing.com'")))

During handling of the above exception, another exception occurred:

Traceback (most recent call last):
  File "/home/airflow/.local/lib/python3.12/site-packages/snowflake/connector/network.py", line 1081, in _request_exec
    raw_ret = session.request(
              ^^^^^^^^^^^^^^^^
  File "/home/airflow/.local/lib/python3.12/site-packages/snowflake/connector/vendored/requests/sessions.py", line 589, in request
    resp = self.send(prep, **send_kwargs)
           ^^^^^^^^^^^^^^^^^^^^^^^^^^^^^^
  File "/home/airflow/.local/lib/python3.12/site-packages/snowflake/connector/vendored/requests/sessions.py", line 703, in send
    r = adapter.send(request, **kwargs)
        ^^^^^^^^^^^^^^^^^^^^^^^^^^^^^^^
  File "/home/airflow/.local/lib/python3.12/site-packages/snowflake/connector/vendored/requests/adapters.py", line 517, in send
    raise SSLError(e, request=request)
snowflake.connector.vendored.requests.exceptions.SSLError: HTTPSConnectionPool(host='gkexgfn-mc38946.aws_eu_west_3.snowflakecomputing.com', port=443): Max retries exceeded with url: /session/v1/login-request?request_id=7d7a2e95-fb3a-4652-9181-7d48da37d5a3&databaseName=VOITURE_DATA&schemaName=PUBLIC&warehouse=COMPUTE_WH&roleName=ACCOUNTADMIN&request_guid=fa2cb6c4-0ab7-430b-b042-e9600eca789f (Caused by SSLError(CertificateError("hostname 'gkexgfn-mc38946.aws_eu_west_3.snowflakecomputing.com' doesn't match either of '*.prod3.us-west-2.snowflakecomputing.com', '*.us-west-2.snowflakecomputing.com', '*.global.snowflakecomputing.com', '*.snowflakecomputing.com', '*.prod3.us-west-2.aws.snowflakecomputing.com'")))

During handling of the above exception, another exception occurred:

Traceback (most recent call last):
  File "/home/airflow/.local/lib/python3.12/site-packages/snowflake/connector/connection.py", line 1432, in _authenticate
    auth.authenticate(
  File "/home/airflow/.local/lib/python3.12/site-packages/snowflake/connector/auth/_auth.py", line 265, in authenticate
    ret = self._rest._post_request(
          ^^^^^^^^^^^^^^^^^^^^^^^^^
  File "/home/airflow/.local/lib/python3.12/site-packages/snowflake/connector/network.py", line 749, in _post_request
    ret = self.fetch(
          ^^^^^^^^^^^
  File "/home/airflow/.local/lib/python3.12/site-packages/snowflake/connector/network.py", line 864, in fetch
    ret = self._request_exec_wrapper(
          ^^^^^^^^^^^^^^^^^^^^^^^^^^^
  File "/home/airflow/.local/lib/python3.12/site-packages/snowflake/connector/network.py", line 992, in _request_exec_wrapper
    raise e
  File "/home/airflow/.local/lib/python3.12/site-packages/snowflake/connector/network.py", line 914, in _request_exec_wrapper
    return_object = self._request_exec(
                    ^^^^^^^^^^^^^^^^^^^
  File "/home/airflow/.local/lib/python3.12/site-packages/snowflake/connector/network.py", line 1151, in _request_exec
    Error.errorhandler_wrapper(
  File "/home/airflow/.local/lib/python3.12/site-packages/snowflake/connector/errors.py", line 283, in errorhandler_wrapper
    handed_over = Error.hand_to_other_handler(
                  ^^^^^^^^^^^^^^^^^^^^^^^^^^^^
  File "/home/airflow/.local/lib/python3.12/site-packages/snowflake/connector/errors.py", line 341, in hand_to_other_handler
    connection.errorhandler(connection, cursor, error_class, error_value)
  File "/home/airflow/.local/lib/python3.12/site-packages/snowflake/connector/errors.py", line 214, in default_errorhandler
    raise error_class(
snowflake.connector.errors.OperationalError: 250003: 250003: Hit non-retryable SSL error, HTTPSConnectionPool(host='gkexgfn-mc38946.aws_eu_west_3.snowflakecomputing.com', port=443): Max retries exceeded with url: /session/v1/login-request?request_id=7d7a2e95-fb3a-4652-9181-7d48da37d5a3&databaseName=VOITURE_DATA&schemaName=PUBLIC&warehouse=COMPUTE_WH&roleName=ACCOUNTADMIN&request_guid=fa2cb6c4-0ab7-430b-b042-e9600eca789f (Caused by SSLError(CertificateError("hostname 'gkexgfn-mc38946.aws_eu_west_3.snowflakecomputing.com' doesn't match either of '*.prod3.us-west-2.snowflakecomputing.com', '*.us-west-2.snowflakecomputing.com', '*.global.snowflakecomputing.com', '*.snowflakecomputing.com', '*.prod3.us-west-2.aws.snowflakecomputing.com'"))).
Verify that the hostnames and port numbers in SYSTEM$ALLOWLIST are added to your firewall's allowed list.
To further troubleshoot your connection you may reference the following article: https://docs.snowflake.com/en/user-guide/client-connectivity-troubleshooting/overview.

The above exception was the direct cause of the following exception:

Traceback (most recent call last):
  File "/home/airflow/.local/lib/python3.12/site-packages/airflow/models/taskinstance.py", line 768, in _execute_task
    result = _execute_callable(context=context, **execute_callable_kwargs)
             ^^^^^^^^^^^^^^^^^^^^^^^^^^^^^^^^^^^^^^^^^^^^^^^^^^^^^^^^^^^^^
  File "/home/airflow/.local/lib/python3.12/site-packages/airflow/models/taskinstance.py", line 734, in _execute_callable
    return ExecutionCallableRunner(
           ^^^^^^^^^^^^^^^^^^^^^^^^
  File "/home/airflow/.local/lib/python3.12/site-packages/airflow/utils/operator_helpers.py", line 252, in run
    return self.func(*args, **kwargs)
           ^^^^^^^^^^^^^^^^^^^^^^^^^^
  File "/home/airflow/.local/lib/python3.12/site-packages/airflow/models/baseoperator.py", line 424, in wrapper
    return func(self, *args, **kwargs)
           ^^^^^^^^^^^^^^^^^^^^^^^^^^^
  File "/home/airflow/.local/lib/python3.12/site-packages/airflow/providers/common/sql/operators/sql.py", line 816, in execute
    records = self.get_db_hook().get_first(self.sql, self.parameters)
              ^^^^^^^^^^^^^^^^^^^^^^^^^^^^^^^^^^^^^^^^^^^^^^^^^^^^^^^
  File "/home/airflow/.local/lib/python3.12/site-packages/airflow/providers/common/sql/hooks/sql.py", line 336, in get_first
    return self.run(sql=sql, parameters=parameters, handler=fetch_one_handler)
           ^^^^^^^^^^^^^^^^^^^^^^^^^^^^^^^^^^^^^^^^^^^^^^^^^^^^^^^^^^^^^^^^^^^
  File "/home/airflow/.local/lib/python3.12/site-packages/airflow/providers/snowflake/hooks/snowflake.py", line 459, in run
    with closing(self.get_conn()) as conn:
                 ^^^^^^^^^^^^^^^
  File "/home/airflow/.local/lib/python3.12/site-packages/airflow/providers/snowflake/hooks/snowflake.py", line 330, in get_conn
    conn = connector.connect(**conn_config)
           ^^^^^^^^^^^^^^^^^^^^^^^^^^^^^^^^
  File "/home/airflow/.local/lib/python3.12/site-packages/snowflake/connector/__init__.py", line 55, in Connect
    return SnowflakeConnection(**kwargs)
           ^^^^^^^^^^^^^^^^^^^^^^^^^^^^^
  File "/home/airflow/.local/lib/python3.12/site-packages/snowflake/connector/connection.py", line 467, in __init__
    self.connect(**kwargs)
  File "/home/airflow/.local/lib/python3.12/site-packages/snowflake/connector/connection.py", line 786, in connect
    self.__open_connection()
  File "/home/airflow/.local/lib/python3.12/site-packages/snowflake/connector/connection.py", line 1116, in __open_connection
    self.authenticate_with_retry(self.auth_class)
  File "/home/airflow/.local/lib/python3.12/site-packages/snowflake/connector/connection.py", line 1404, in authenticate_with_retry
    self._authenticate(auth_instance)
  File "/home/airflow/.local/lib/python3.12/site-packages/snowflake/connector/connection.py", line 1478, in _authenticate
    raise auth_op from e
  File "/home/airflow/.local/lib/python3.12/site-packages/snowflake/connector/connection.py", line 1453, in _authenticate
    auth_instance.handle_timeout(
  File "/home/airflow/.local/lib/python3.12/site-packages/snowflake/connector/auth/by_plugin.py", line 213, in handle_timeout
    raise error
snowflake.connector.errors.OperationalError: 250001: 250001: Could not connect to Snowflake backend after 2 attempt(s).Aborting
Verify that the hostnames and port numbers in SYSTEM$ALLOWLIST are added to your firewall's allowed list.
To further troubleshoot your connection you may reference the following article: https://docs.snowflake.com/en/user-guide/client-connectivity-troubleshooting/overview.
[2025-04-30T23:43:00.998+0000] {taskinstance.py:1226} INFO - Marking task as UP_FOR_RETRY. dag_id=test_snowflake_connection, task_id=test_snowflake_connection, run_id=manual__2025-04-30T23:42:40.191819+00:00, execution_date=20250430T234240, start_date=20250430T234254, end_date=20250430T234300
[2025-04-30T23:43:01.076+0000] {taskinstance.py:341} INFO - ::group::Post task execution logs
[2025-04-30T23:43:01.077+0000] {standard_task_runner.py:124} ERROR - Failed to execute job 10 for task test_snowflake_connection (250001: 250001: Could not connect to Snowflake backend after 2 attempt(s).Aborting
Verify that the hostnames and port numbers in SYSTEM$ALLOWLIST are added to your firewall's allowed list.
To further troubleshoot your connection you may reference the following article: https://docs.snowflake.com/en/user-guide/client-connectivity-troubleshooting/overview.; 38)
Traceback (most recent call last):
  File "/home/airflow/.local/lib/python3.12/site-packages/snowflake/connector/vendored/urllib3/connectionpool.py", line 715, in urlopen
    httplib_response = self._make_request(
                       ^^^^^^^^^^^^^^^^^^^
  File "/home/airflow/.local/lib/python3.12/site-packages/snowflake/connector/vendored/urllib3/connectionpool.py", line 404, in _make_request
    self._validate_conn(conn)
  File "/home/airflow/.local/lib/python3.12/site-packages/snowflake/connector/vendored/urllib3/connectionpool.py", line 1058, in _validate_conn
    conn.connect()
  File "/home/airflow/.local/lib/python3.12/site-packages/snowflake/connector/vendored/urllib3/connection.py", line 472, in connect
    _match_hostname(cert, self.assert_hostname or server_hostname)
  File "/home/airflow/.local/lib/python3.12/site-packages/snowflake/connector/vendored/urllib3/connection.py", line 545, in _match_hostname
    match_hostname(cert, asserted_hostname)
  File "/home/airflow/.local/lib/python3.12/site-packages/snowflake/connector/vendored/urllib3/util/ssl_match_hostname.py", line 150, in match_hostname
    raise CertificateError(
snowflake.connector.vendored.urllib3.util.ssl_match_hostname.CertificateError: hostname 'gkexgfn-mc38946.aws_eu_west_3.snowflakecomputing.com' doesn't match either of '*.prod3.us-west-2.snowflakecomputing.com', '*.us-west-2.snowflakecomputing.com', '*.global.snowflakecomputing.com', '*.snowflakecomputing.com', '*.prod3.us-west-2.aws.snowflakecomputing.com'

During handling of the above exception, another exception occurred:

Traceback (most recent call last):
  File "/home/airflow/.local/lib/python3.12/site-packages/snowflake/connector/vendored/requests/adapters.py", line 486, in send
    resp = conn.urlopen(
           ^^^^^^^^^^^^^
  File "/home/airflow/.local/lib/python3.12/site-packages/snowflake/connector/vendored/urllib3/connectionpool.py", line 827, in urlopen
    return self.urlopen(
           ^^^^^^^^^^^^^
  File "/home/airflow/.local/lib/python3.12/site-packages/snowflake/connector/vendored/urllib3/connectionpool.py", line 799, in urlopen
    retries = retries.increment(
              ^^^^^^^^^^^^^^^^^^
  File "/home/airflow/.local/lib/python3.12/site-packages/snowflake/connector/vendored/urllib3/util/retry.py", line 592, in increment
    raise MaxRetryError(_pool, url, error or ResponseError(cause))
snowflake.connector.vendored.urllib3.exceptions.MaxRetryError: HTTPSConnectionPool(host='gkexgfn-mc38946.aws_eu_west_3.snowflakecomputing.com', port=443): Max retries exceeded with url: /session/v1/login-request?request_id=7d7a2e95-fb3a-4652-9181-7d48da37d5a3&databaseName=VOITURE_DATA&schemaName=PUBLIC&warehouse=COMPUTE_WH&roleName=ACCOUNTADMIN&request_guid=fa2cb6c4-0ab7-430b-b042-e9600eca789f (Caused by SSLError(CertificateError("hostname 'gkexgfn-mc38946.aws_eu_west_3.snowflakecomputing.com' doesn't match either of '*.prod3.us-west-2.snowflakecomputing.com', '*.us-west-2.snowflakecomputing.com', '*.global.snowflakecomputing.com', '*.snowflakecomputing.com', '*.prod3.us-west-2.aws.snowflakecomputing.com'")))

During handling of the above exception, another exception occurred:

Traceback (most recent call last):
  File "/home/airflow/.local/lib/python3.12/site-packages/snowflake/connector/network.py", line 1081, in _request_exec
    raw_ret = session.request(
              ^^^^^^^^^^^^^^^^
  File "/home/airflow/.local/lib/python3.12/site-packages/snowflake/connector/vendored/requests/sessions.py", line 589, in request
    resp = self.send(prep, **send_kwargs)
           ^^^^^^^^^^^^^^^^^^^^^^^^^^^^^^
  File "/home/airflow/.local/lib/python3.12/site-packages/snowflake/connector/vendored/requests/sessions.py", line 703, in send
    r = adapter.send(request, **kwargs)
        ^^^^^^^^^^^^^^^^^^^^^^^^^^^^^^^
  File "/home/airflow/.local/lib/python3.12/site-packages/snowflake/connector/vendored/requests/adapters.py", line 517, in send
    raise SSLError(e, request=request)
snowflake.connector.vendored.requests.exceptions.SSLError: HTTPSConnectionPool(host='gkexgfn-mc38946.aws_eu_west_3.snowflakecomputing.com', port=443): Max retries exceeded with url: /session/v1/login-request?request_id=7d7a2e95-fb3a-4652-9181-7d48da37d5a3&databaseName=VOITURE_DATA&schemaName=PUBLIC&warehouse=COMPUTE_WH&roleName=ACCOUNTADMIN&request_guid=fa2cb6c4-0ab7-430b-b042-e9600eca789f (Caused by SSLError(CertificateError("hostname 'gkexgfn-mc38946.aws_eu_west_3.snowflakecomputing.com' doesn't match either of '*.prod3.us-west-2.snowflakecomputing.com', '*.us-west-2.snowflakecomputing.com', '*.global.snowflakecomputing.com', '*.snowflakecomputing.com', '*.prod3.us-west-2.aws.snowflakecomputing.com'")))

During handling of the above exception, another exception occurred:

Traceback (most recent call last):
  File "/home/airflow/.local/lib/python3.12/site-packages/snowflake/connector/connection.py", line 1432, in _authenticate
    auth.authenticate(
  File "/home/airflow/.local/lib/python3.12/site-packages/snowflake/connector/auth/_auth.py", line 265, in authenticate
    ret = self._rest._post_request(
          ^^^^^^^^^^^^^^^^^^^^^^^^^
  File "/home/airflow/.local/lib/python3.12/site-packages/snowflake/connector/network.py", line 749, in _post_request
    ret = self.fetch(
          ^^^^^^^^^^^
  File "/home/airflow/.local/lib/python3.12/site-packages/snowflake/connector/network.py", line 864, in fetch
    ret = self._request_exec_wrapper(
          ^^^^^^^^^^^^^^^^^^^^^^^^^^^
  File "/home/airflow/.local/lib/python3.12/site-packages/snowflake/connector/network.py", line 992, in _request_exec_wrapper
    raise e
  File "/home/airflow/.local/lib/python3.12/site-packages/snowflake/connector/network.py", line 914, in _request_exec_wrapper
    return_object = self._request_exec(
                    ^^^^^^^^^^^^^^^^^^^
  File "/home/airflow/.local/lib/python3.12/site-packages/snowflake/connector/network.py", line 1151, in _request_exec
    Error.errorhandler_wrapper(
  File "/home/airflow/.local/lib/python3.12/site-packages/snowflake/connector/errors.py", line 283, in errorhandler_wrapper
    handed_over = Error.hand_to_other_handler(
                  ^^^^^^^^^^^^^^^^^^^^^^^^^^^^
  File "/home/airflow/.local/lib/python3.12/site-packages/snowflake/connector/errors.py", line 341, in hand_to_other_handler
    connection.errorhandler(connection, cursor, error_class, error_value)
  File "/home/airflow/.local/lib/python3.12/site-packages/snowflake/connector/errors.py", line 214, in default_errorhandler
    raise error_class(
snowflake.connector.errors.OperationalError: 250003: 250003: Hit non-retryable SSL error, HTTPSConnectionPool(host='gkexgfn-mc38946.aws_eu_west_3.snowflakecomputing.com', port=443): Max retries exceeded with url: /session/v1/login-request?request_id=7d7a2e95-fb3a-4652-9181-7d48da37d5a3&databaseName=VOITURE_DATA&schemaName=PUBLIC&warehouse=COMPUTE_WH&roleName=ACCOUNTADMIN&request_guid=fa2cb6c4-0ab7-430b-b042-e9600eca789f (Caused by SSLError(CertificateError("hostname 'gkexgfn-mc38946.aws_eu_west_3.snowflakecomputing.com' doesn't match either of '*.prod3.us-west-2.snowflakecomputing.com', '*.us-west-2.snowflakecomputing.com', '*.global.snowflakecomputing.com', '*.snowflakecomputing.com', '*.prod3.us-west-2.aws.snowflakecomputing.com'"))).
Verify that the hostnames and port numbers in SYSTEM$ALLOWLIST are added to your firewall's allowed list.
To further troubleshoot your connection you may reference the following article: https://docs.snowflake.com/en/user-guide/client-connectivity-troubleshooting/overview.

The above exception was the direct cause of the following exception:

Traceback (most recent call last):
  File "/home/airflow/.local/lib/python3.12/site-packages/airflow/task/task_runner/standard_task_runner.py", line 117, in _start_by_fork
    ret = args.func(args, dag=self.dag)
          ^^^^^^^^^^^^^^^^^^^^^^^^^^^^^
  File "/home/airflow/.local/lib/python3.12/site-packages/airflow/cli/cli_config.py", line 49, in command
    return func(*args, **kwargs)
           ^^^^^^^^^^^^^^^^^^^^^
  File "/home/airflow/.local/lib/python3.12/site-packages/airflow/utils/cli.py", line 116, in wrapper
    return f(*args, **kwargs)
           ^^^^^^^^^^^^^^^^^^
  File "/home/airflow/.local/lib/python3.12/site-packages/airflow/cli/commands/task_command.py", line 483, in task_run
    task_return_code = _run_task_by_selected_method(args, _dag, ti)
                       ^^^^^^^^^^^^^^^^^^^^^^^^^^^^^^^^^^^^^^^^^^^^
  File "/home/airflow/.local/lib/python3.12/site-packages/airflow/cli/commands/task_command.py", line 256, in _run_task_by_selected_method
    return _run_raw_task(args, ti)
           ^^^^^^^^^^^^^^^^^^^^^^^
  File "/home/airflow/.local/lib/python3.12/site-packages/airflow/cli/commands/task_command.py", line 341, in _run_raw_task
    return ti._run_raw_task(
           ^^^^^^^^^^^^^^^^^
  File "/home/airflow/.local/lib/python3.12/site-packages/airflow/utils/session.py", line 97, in wrapper
    return func(*args, session=session, **kwargs)
           ^^^^^^^^^^^^^^^^^^^^^^^^^^^^^^^^^^^^^^
  File "/home/airflow/.local/lib/python3.12/site-packages/airflow/models/taskinstance.py", line 3006, in _run_raw_task
    return _run_raw_task(
           ^^^^^^^^^^^^^^
  File "/home/airflow/.local/lib/python3.12/site-packages/airflow/models/taskinstance.py", line 274, in _run_raw_task
    TaskInstance._execute_task_with_callbacks(
  File "/home/airflow/.local/lib/python3.12/site-packages/airflow/models/taskinstance.py", line 3161, in _execute_task_with_callbacks
    result = self._execute_task(context, task_orig)
             ^^^^^^^^^^^^^^^^^^^^^^^^^^^^^^^^^^^^^^
  File "/home/airflow/.local/lib/python3.12/site-packages/airflow/models/taskinstance.py", line 3185, in _execute_task
    return _execute_task(self, context, task_orig)
           ^^^^^^^^^^^^^^^^^^^^^^^^^^^^^^^^^^^^^^^
  File "/home/airflow/.local/lib/python3.12/site-packages/airflow/models/taskinstance.py", line 768, in _execute_task
    result = _execute_callable(context=context, **execute_callable_kwargs)
             ^^^^^^^^^^^^^^^^^^^^^^^^^^^^^^^^^^^^^^^^^^^^^^^^^^^^^^^^^^^^^
  File "/home/airflow/.local/lib/python3.12/site-packages/airflow/models/taskinstance.py", line 734, in _execute_callable
    return ExecutionCallableRunner(
           ^^^^^^^^^^^^^^^^^^^^^^^^
  File "/home/airflow/.local/lib/python3.12/site-packages/airflow/utils/operator_helpers.py", line 252, in run
    return self.func(*args, **kwargs)
           ^^^^^^^^^^^^^^^^^^^^^^^^^^
  File "/home/airflow/.local/lib/python3.12/site-packages/airflow/models/baseoperator.py", line 424, in wrapper
    return func(self, *args, **kwargs)
           ^^^^^^^^^^^^^^^^^^^^^^^^^^^
  File "/home/airflow/.local/lib/python3.12/site-packages/airflow/providers/common/sql/operators/sql.py", line 816, in execute
    records = self.get_db_hook().get_first(self.sql, self.parameters)
              ^^^^^^^^^^^^^^^^^^^^^^^^^^^^^^^^^^^^^^^^^^^^^^^^^^^^^^^
  File "/home/airflow/.local/lib/python3.12/site-packages/airflow/providers/common/sql/hooks/sql.py", line 336, in get_first
    return self.run(sql=sql, parameters=parameters, handler=fetch_one_handler)
           ^^^^^^^^^^^^^^^^^^^^^^^^^^^^^^^^^^^^^^^^^^^^^^^^^^^^^^^^^^^^^^^^^^^
  File "/home/airflow/.local/lib/python3.12/site-packages/airflow/providers/snowflake/hooks/snowflake.py", line 459, in run
    with closing(self.get_conn()) as conn:
                 ^^^^^^^^^^^^^^^
  File "/home/airflow/.local/lib/python3.12/site-packages/airflow/providers/snowflake/hooks/snowflake.py", line 330, in get_conn
    conn = connector.connect(**conn_config)
           ^^^^^^^^^^^^^^^^^^^^^^^^^^^^^^^^
  File "/home/airflow/.local/lib/python3.12/site-packages/snowflake/connector/__init__.py", line 55, in Connect
    return SnowflakeConnection(**kwargs)
           ^^^^^^^^^^^^^^^^^^^^^^^^^^^^^
  File "/home/airflow/.local/lib/python3.12/site-packages/snowflake/connector/connection.py", line 467, in __init__
    self.connect(**kwargs)
  File "/home/airflow/.local/lib/python3.12/site-packages/snowflake/connector/connection.py", line 786, in connect
    self.__open_connection()
  File "/home/airflow/.local/lib/python3.12/site-packages/snowflake/connector/connection.py", line 1116, in __open_connection
    self.authenticate_with_retry(self.auth_class)
  File "/home/airflow/.local/lib/python3.12/site-packages/snowflake/connector/connection.py", line 1404, in authenticate_with_retry
    self._authenticate(auth_instance)
  File "/home/airflow/.local/lib/python3.12/site-packages/snowflake/connector/connection.py", line 1478, in _authenticate
    raise auth_op from e
  File "/home/airflow/.local/lib/python3.12/site-packages/snowflake/connector/connection.py", line 1453, in _authenticate
    auth_instance.handle_timeout(
  File "/home/airflow/.local/lib/python3.12/site-packages/snowflake/connector/auth/by_plugin.py", line 213, in handle_timeout
    raise error
snowflake.connector.errors.OperationalError: 250001: 250001: Could not connect to Snowflake backend after 2 attempt(s).Aborting
Verify that the hostnames and port numbers in SYSTEM$ALLOWLIST are added to your firewall's allowed list.
To further troubleshoot your connection you may reference the following article: https://docs.snowflake.com/en/user-guide/client-connectivity-troubleshooting/overview.
[2025-04-30T23:43:01.118+0000] {local_task_job_runner.py:266} INFO - Task exited with return code 1
[2025-04-30T23:43:01.145+0000] {taskinstance.py:3901} INFO - 0 downstream tasks scheduled from follow-on schedule check
[2025-04-30T23:43:01.150+0000] {local_task_job_runner.py:245} INFO - ::endgroup::
