[2025-04-30T23:19:03.805+0000] {local_task_job_runner.py:123} INFO - ::group::Pre task execution logs
[2025-04-30T23:19:04.497+0000] {taskinstance.py:2614} INFO - Dependencies all met for dep_context=non-requeueable deps ti=<TaskInstance: store_data_in_snowflake.store_data_in_snowflake manual__2025-04-30T23:18:28.239024+00:00 [queued]>
[2025-04-30T23:19:04.520+0000] {taskinstance.py:2614} INFO - Dependencies all met for dep_context=requeueable deps ti=<TaskInstance: store_data_in_snowflake.store_data_in_snowflake manual__2025-04-30T23:18:28.239024+00:00 [queued]>
[2025-04-30T23:19:04.743+0000] {taskinstance.py:2867} INFO - Starting attempt 1 of 2
[2025-04-30T23:19:05.541+0000] {taskinstance.py:2890} INFO - Executing <Task(SnowflakeCheckOperator): store_data_in_snowflake> on 2025-04-30 23:18:28.239024+00:00
[2025-04-30T23:19:05.637+0000] {standard_task_runner.py:104} INFO - Running: ['***', 'tasks', 'run', 'store_data_in_snowflake', 'store_data_in_snowflake', 'manual__2025-04-30T23:18:28.239024+00:00', '--job-id', '4', '--raw', '--subdir', 'DAGS_FOLDER/dataframe_in_snowflake.py', '--cfg-path', '/tmp/tmp40ormnss']
[2025-04-30T23:19:05.640+0000] {standard_task_runner.py:105} INFO - Job 4: Subtask store_data_in_snowflake
[2025-04-30T23:19:05.642+0000] {logging_mixin.py:190} WARNING - /home/***/.local/lib/python3.12/site-packages/***/task/task_runner/standard_task_runner.py:70 DeprecationWarning: This process (pid=40) is multi-threaded, use of fork() may lead to deadlocks in the child.
[2025-04-30T23:19:05.654+0000] {standard_task_runner.py:72} INFO - Started process 47 to run task
[2025-04-30T23:19:05.830+0000] {task_command.py:467} INFO - Running <TaskInstance: store_data_in_snowflake.store_data_in_snowflake manual__2025-04-30T23:18:28.239024+00:00 [running]> on host 51455b06f8e1
[2025-04-30T23:19:06.345+0000] {taskinstance.py:3134} INFO - Exporting env vars: AIRFLOW_CTX_DAG_OWNER='***' AIRFLOW_CTX_DAG_ID='store_data_in_snowflake' AIRFLOW_CTX_TASK_ID='store_data_in_snowflake' AIRFLOW_CTX_EXECUTION_DATE='2025-04-30T23:18:28.239024+00:00' AIRFLOW_CTX_TRY_NUMBER='1' AIRFLOW_CTX_DAG_RUN_ID='manual__2025-04-30T23:18:28.239024+00:00'
[2025-04-30T23:19:06.349+0000] {taskinstance.py:732} INFO - ::endgroup::
[2025-04-30T23:19:06.389+0000] {sql.py:815} INFO - Executing SQL check: 
        CREATE TABLE IF NOT EXISTS PUBLIC.TEST_TABLE (
            column1 STRING,
            column2 STRING
        );
        INSERT INTO PUBLIC.TEST_TABLE (column1, column2)
        VALUES ('value1', 'value2');
        
[2025-04-30T23:19:06.428+0000] {base.py:84} INFO - Retrieving connection 'snowflake_default'
[2025-04-30T23:19:06.634+0000] {base.py:84} INFO - Retrieving connection 'snowflake_default'
[2025-04-30T23:19:06.640+0000] {connection.py:424} INFO - Snowflake Connector for Python Version: 3.13.2, Python Version: 3.12.9, Platform: Linux-5.15.167.4-microsoft-standard-WSL2-x86_64-with-glibc2.36
[2025-04-30T23:19:06.645+0000] {connection.py:1213} INFO - Connecting to GLOBAL Snowflake domain
[2025-04-30T23:19:06.649+0000] {taskinstance.py:3313} ERROR - Task failed with exception
Traceback (most recent call last):
  File "/home/airflow/.local/lib/python3.12/site-packages/airflow/models/taskinstance.py", line 768, in _execute_task
    result = _execute_callable(context=context, **execute_callable_kwargs)
             ^^^^^^^^^^^^^^^^^^^^^^^^^^^^^^^^^^^^^^^^^^^^^^^^^^^^^^^^^^^^^
  File "/home/airflow/.local/lib/python3.12/site-packages/airflow/models/taskinstance.py", line 734, in _execute_callable
    return ExecutionCallableRunner(
           ^^^^^^^^^^^^^^^^^^^^^^^^
  File "/home/airflow/.local/lib/python3.12/site-packages/airflow/utils/operator_helpers.py", line 252, in run
    return self.func(*args, **kwargs)
           ^^^^^^^^^^^^^^^^^^^^^^^^^^
  File "/home/airflow/.local/lib/python3.12/site-packages/airflow/models/baseoperator.py", line 424, in wrapper
    return func(self, *args, **kwargs)
           ^^^^^^^^^^^^^^^^^^^^^^^^^^^
  File "/home/airflow/.local/lib/python3.12/site-packages/airflow/providers/common/sql/operators/sql.py", line 816, in execute
    records = self.get_db_hook().get_first(self.sql, self.parameters)
              ^^^^^^^^^^^^^^^^^^^^^^^^^^^^^^^^^^^^^^^^^^^^^^^^^^^^^^^
  File "/home/airflow/.local/lib/python3.12/site-packages/airflow/providers/common/sql/hooks/sql.py", line 336, in get_first
    return self.run(sql=sql, parameters=parameters, handler=fetch_one_handler)
           ^^^^^^^^^^^^^^^^^^^^^^^^^^^^^^^^^^^^^^^^^^^^^^^^^^^^^^^^^^^^^^^^^^^
  File "/home/airflow/.local/lib/python3.12/site-packages/airflow/providers/snowflake/hooks/snowflake.py", line 459, in run
    with closing(self.get_conn()) as conn:
                 ^^^^^^^^^^^^^^^
  File "/home/airflow/.local/lib/python3.12/site-packages/airflow/providers/snowflake/hooks/snowflake.py", line 330, in get_conn
    conn = connector.connect(**conn_config)
           ^^^^^^^^^^^^^^^^^^^^^^^^^^^^^^^^
  File "/home/airflow/.local/lib/python3.12/site-packages/snowflake/connector/__init__.py", line 55, in Connect
    return SnowflakeConnection(**kwargs)
           ^^^^^^^^^^^^^^^^^^^^^^^^^^^^^
  File "/home/airflow/.local/lib/python3.12/site-packages/snowflake/connector/connection.py", line 467, in __init__
    self.connect(**kwargs)
  File "/home/airflow/.local/lib/python3.12/site-packages/snowflake/connector/connection.py", line 747, in connect
    self.__config(**kwargs)
  File "/home/airflow/.local/lib/python3.12/site-packages/snowflake/connector/connection.py", line 1272, in __config
    Error.errorhandler_wrapper(
  File "/home/airflow/.local/lib/python3.12/site-packages/snowflake/connector/errors.py", line 283, in errorhandler_wrapper
    handed_over = Error.hand_to_other_handler(
                  ^^^^^^^^^^^^^^^^^^^^^^^^^^^^
  File "/home/airflow/.local/lib/python3.12/site-packages/snowflake/connector/errors.py", line 341, in hand_to_other_handler
    connection.errorhandler(connection, cursor, error_class, error_value)
  File "/home/airflow/.local/lib/python3.12/site-packages/snowflake/connector/errors.py", line 214, in default_errorhandler
    raise error_class(
snowflake.connector.errors.ProgrammingError: 251001: 251001: Account must be specified
[2025-04-30T23:19:06.684+0000] {taskinstance.py:1226} INFO - Marking task as UP_FOR_RETRY. dag_id=store_data_in_snowflake, task_id=store_data_in_snowflake, run_id=manual__2025-04-30T23:18:28.239024+00:00, execution_date=20250430T231828, start_date=20250430T231904, end_date=20250430T231906
[2025-04-30T23:19:06.822+0000] {taskinstance.py:341} INFO - ::group::Post task execution logs
[2025-04-30T23:19:06.827+0000] {standard_task_runner.py:124} ERROR - Failed to execute job 4 for task store_data_in_snowflake (251001: 251001: Account must be specified; 47)
Traceback (most recent call last):
  File "/home/airflow/.local/lib/python3.12/site-packages/airflow/task/task_runner/standard_task_runner.py", line 117, in _start_by_fork
    ret = args.func(args, dag=self.dag)
          ^^^^^^^^^^^^^^^^^^^^^^^^^^^^^
  File "/home/airflow/.local/lib/python3.12/site-packages/airflow/cli/cli_config.py", line 49, in command
    return func(*args, **kwargs)
           ^^^^^^^^^^^^^^^^^^^^^
  File "/home/airflow/.local/lib/python3.12/site-packages/airflow/utils/cli.py", line 116, in wrapper
    return f(*args, **kwargs)
           ^^^^^^^^^^^^^^^^^^
  File "/home/airflow/.local/lib/python3.12/site-packages/airflow/cli/commands/task_command.py", line 483, in task_run
    task_return_code = _run_task_by_selected_method(args, _dag, ti)
                       ^^^^^^^^^^^^^^^^^^^^^^^^^^^^^^^^^^^^^^^^^^^^
  File "/home/airflow/.local/lib/python3.12/site-packages/airflow/cli/commands/task_command.py", line 256, in _run_task_by_selected_method
    return _run_raw_task(args, ti)
           ^^^^^^^^^^^^^^^^^^^^^^^
  File "/home/airflow/.local/lib/python3.12/site-packages/airflow/cli/commands/task_command.py", line 341, in _run_raw_task
    return ti._run_raw_task(
           ^^^^^^^^^^^^^^^^^
  File "/home/airflow/.local/lib/python3.12/site-packages/airflow/utils/session.py", line 97, in wrapper
    return func(*args, session=session, **kwargs)
           ^^^^^^^^^^^^^^^^^^^^^^^^^^^^^^^^^^^^^^
  File "/home/airflow/.local/lib/python3.12/site-packages/airflow/models/taskinstance.py", line 3006, in _run_raw_task
    return _run_raw_task(
           ^^^^^^^^^^^^^^
  File "/home/airflow/.local/lib/python3.12/site-packages/airflow/models/taskinstance.py", line 274, in _run_raw_task
    TaskInstance._execute_task_with_callbacks(
  File "/home/airflow/.local/lib/python3.12/site-packages/airflow/models/taskinstance.py", line 3161, in _execute_task_with_callbacks
    result = self._execute_task(context, task_orig)
             ^^^^^^^^^^^^^^^^^^^^^^^^^^^^^^^^^^^^^^
  File "/home/airflow/.local/lib/python3.12/site-packages/airflow/models/taskinstance.py", line 3185, in _execute_task
    return _execute_task(self, context, task_orig)
           ^^^^^^^^^^^^^^^^^^^^^^^^^^^^^^^^^^^^^^^
  File "/home/airflow/.local/lib/python3.12/site-packages/airflow/models/taskinstance.py", line 768, in _execute_task
    result = _execute_callable(context=context, **execute_callable_kwargs)
             ^^^^^^^^^^^^^^^^^^^^^^^^^^^^^^^^^^^^^^^^^^^^^^^^^^^^^^^^^^^^^
  File "/home/airflow/.local/lib/python3.12/site-packages/airflow/models/taskinstance.py", line 734, in _execute_callable
    return ExecutionCallableRunner(
           ^^^^^^^^^^^^^^^^^^^^^^^^
  File "/home/airflow/.local/lib/python3.12/site-packages/airflow/utils/operator_helpers.py", line 252, in run
    return self.func(*args, **kwargs)
           ^^^^^^^^^^^^^^^^^^^^^^^^^^
  File "/home/airflow/.local/lib/python3.12/site-packages/airflow/models/baseoperator.py", line 424, in wrapper
    return func(self, *args, **kwargs)
           ^^^^^^^^^^^^^^^^^^^^^^^^^^^
  File "/home/airflow/.local/lib/python3.12/site-packages/airflow/providers/common/sql/operators/sql.py", line 816, in execute
    records = self.get_db_hook().get_first(self.sql, self.parameters)
              ^^^^^^^^^^^^^^^^^^^^^^^^^^^^^^^^^^^^^^^^^^^^^^^^^^^^^^^
  File "/home/airflow/.local/lib/python3.12/site-packages/airflow/providers/common/sql/hooks/sql.py", line 336, in get_first
    return self.run(sql=sql, parameters=parameters, handler=fetch_one_handler)
           ^^^^^^^^^^^^^^^^^^^^^^^^^^^^^^^^^^^^^^^^^^^^^^^^^^^^^^^^^^^^^^^^^^^
  File "/home/airflow/.local/lib/python3.12/site-packages/airflow/providers/snowflake/hooks/snowflake.py", line 459, in run
    with closing(self.get_conn()) as conn:
                 ^^^^^^^^^^^^^^^
  File "/home/airflow/.local/lib/python3.12/site-packages/airflow/providers/snowflake/hooks/snowflake.py", line 330, in get_conn
    conn = connector.connect(**conn_config)
           ^^^^^^^^^^^^^^^^^^^^^^^^^^^^^^^^
  File "/home/airflow/.local/lib/python3.12/site-packages/snowflake/connector/__init__.py", line 55, in Connect
    return SnowflakeConnection(**kwargs)
           ^^^^^^^^^^^^^^^^^^^^^^^^^^^^^
  File "/home/airflow/.local/lib/python3.12/site-packages/snowflake/connector/connection.py", line 467, in __init__
    self.connect(**kwargs)
  File "/home/airflow/.local/lib/python3.12/site-packages/snowflake/connector/connection.py", line 747, in connect
    self.__config(**kwargs)
  File "/home/airflow/.local/lib/python3.12/site-packages/snowflake/connector/connection.py", line 1272, in __config
    Error.errorhandler_wrapper(
  File "/home/airflow/.local/lib/python3.12/site-packages/snowflake/connector/errors.py", line 283, in errorhandler_wrapper
    handed_over = Error.hand_to_other_handler(
                  ^^^^^^^^^^^^^^^^^^^^^^^^^^^^
  File "/home/airflow/.local/lib/python3.12/site-packages/snowflake/connector/errors.py", line 341, in hand_to_other_handler
    connection.errorhandler(connection, cursor, error_class, error_value)
  File "/home/airflow/.local/lib/python3.12/site-packages/snowflake/connector/errors.py", line 214, in default_errorhandler
    raise error_class(
snowflake.connector.errors.ProgrammingError: 251001: 251001: Account must be specified
[2025-04-30T23:19:06.903+0000] {local_task_job_runner.py:266} INFO - Task exited with return code 1
[2025-04-30T23:19:06.956+0000] {taskinstance.py:3901} INFO - 0 downstream tasks scheduled from follow-on schedule check
[2025-04-30T23:19:06.969+0000] {local_task_job_runner.py:245} INFO - ::endgroup::
